{
 "cells": [
  {
   "cell_type": "code",
   "execution_count": 1,
   "id": "df6b1f78",
   "metadata": {},
   "outputs": [
    {
     "name": "stdout",
     "output_type": "stream",
     "text": [
      "         Date       Open       High        Low      Close  Adj Close   Volume\n",
      "0  26/07/2021  19.299999  19.719999  19.299999  19.700001  19.700001  2535500\n",
      "1  27/07/2021  19.280001  19.370001  19.070000  19.270000  19.270000  6127800\n",
      "2  28/07/2021  19.190001  19.459999  19.070000  19.340000  19.340000  1715500\n",
      "3  29/07/2021  19.610001  19.900000  19.590000  19.820000  19.820000  1011000\n",
      "4  30/07/2021  19.650000  19.879999  19.620001  19.680000  19.680000  1055000\n"
     ]
    }
   ],
   "source": [
    "import pandas as pd\n",
    "import numpy as np\n",
    "import matplotlib.pyplot as plt\n",
    "\n",
    "\n",
    "data = pd.read_csv(\"C:/Users/henry/Downloads/TTM.csv\")\n",
    "print(data.head())"
   ]
  },
  {
   "cell_type": "code",
   "execution_count": 11,
   "id": "427f726c",
   "metadata": {},
   "outputs": [
    {
     "ename": "IndexError",
     "evalue": "tuple index out of range",
     "output_type": "error",
     "traceback": [
      "\u001b[1;31m---------------------------------------------------------------------------\u001b[0m",
      "\u001b[1;31mIndexError\u001b[0m                                Traceback (most recent call last)",
      "Input \u001b[1;32mIn [11]\u001b[0m, in \u001b[0;36m<cell line: 6>\u001b[1;34m()\u001b[0m\n\u001b[0;32m      4\u001b[0m \u001b[38;5;28;01mfrom\u001b[39;00m \u001b[38;5;21;01msklearn\u001b[39;00m\u001b[38;5;21;01m.\u001b[39;00m\u001b[38;5;21;01mmodel_selection\u001b[39;00m \u001b[38;5;28;01mimport\u001b[39;00m train_test_split\n\u001b[0;32m      5\u001b[0m Xtrain, Xtest, ytrain, ytest \u001b[38;5;241m=\u001b[39m train_test_split(X, y, test_size\u001b[38;5;241m=\u001b[39m\u001b[38;5;241m0.2\u001b[39m, random_state\u001b[38;5;241m=\u001b[39m\u001b[38;5;241m42\u001b[39m)\n\u001b[1;32m----> 6\u001b[0m Xtrain\u001b[38;5;241m.\u001b[39mshape[\u001b[38;5;241m0\u001b[39m]\u001b[38;5;241m=\u001b[39m\u001b[43mXtrain\u001b[49m\u001b[38;5;241;43m.\u001b[39;49m\u001b[43mshape\u001b[49m\u001b[43m[\u001b[49m\u001b[38;5;241;43m1\u001b[39;49m\u001b[43m]\u001b[49m, \u001b[38;5;241m1\u001b[39m\n",
      "\u001b[1;31mIndexError\u001b[0m: tuple index out of range"
     ]
    }
   ],
   "source": [
    "arr=data.to_numpy()\n",
    "X=arr[:, 1]\n",
    "y=arr[:, 4]\n",
    "from sklearn.model_selection import train_test_split\n",
    "Xtrain, Xtest, ytrain, ytest = train_test_split(X, y, test_size=0.2, random_state=42)"
   ]
  },
  {
   "cell_type": "code",
   "execution_count": 12,
   "id": "058a0d52",
   "metadata": {},
   "outputs": [
    {
     "name": "stdout",
     "output_type": "stream",
     "text": [
      "Model: \"sequential_2\"\n",
      "_________________________________________________________________\n",
      " Layer (type)                Output Shape              Param #   \n",
      "=================================================================\n",
      " lstm (LSTM)                 (None, 200, 128)          66560     \n",
      "                                                                 \n",
      " lstm_1 (LSTM)               (None, 64)                49408     \n",
      "                                                                 \n",
      " dense (Dense)               (None, 25)                1625      \n",
      "                                                                 \n",
      " dense_1 (Dense)             (None, 1)                 26        \n",
      "                                                                 \n",
      "=================================================================\n",
      "Total params: 117,619\n",
      "Trainable params: 117,619\n",
      "Non-trainable params: 0\n",
      "_________________________________________________________________\n"
     ]
    }
   ],
   "source": [
    "from keras.models import Sequential\n",
    "from keras.layers import Dense, LSTM\n",
    "model = Sequential()\n",
    "model.add(LSTM(128, return_sequences=True, input_shape= (Xtrain.shape[0], 1)))\n",
    "model.add(LSTM(64, return_sequences=False))\n",
    "model.add(Dense(25))\n",
    "model.add(Dense(1))\n",
    "model.summary()"
   ]
  },
  {
   "cell_type": "code",
   "execution_count": 18,
   "id": "f5ba5c7b",
   "metadata": {},
   "outputs": [
    {
     "name": "stdout",
     "output_type": "stream",
     "text": [
      "Epoch 1/40\n",
      "WARNING:tensorflow:Model was constructed with shape (None, 200, 1) for input KerasTensor(type_spec=TensorSpec(shape=(None, 200, 1), dtype=tf.float32, name='lstm_input'), name='lstm_input', description=\"created by layer 'lstm_input'\"), but it was called on an input with incompatible shape (None,).\n"
     ]
    },
    {
     "ename": "ValueError",
     "evalue": "in user code:\n\n    File \"C:\\Users\\henry\\miniconda3\\envs\\jupyter_env\\lib\\site-packages\\keras\\engine\\training.py\", line 1051, in train_function  *\n        return step_function(self, iterator)\n    File \"C:\\Users\\henry\\miniconda3\\envs\\jupyter_env\\lib\\site-packages\\keras\\engine\\training.py\", line 1040, in step_function  **\n        outputs = model.distribute_strategy.run(run_step, args=(data,))\n    File \"C:\\Users\\henry\\miniconda3\\envs\\jupyter_env\\lib\\site-packages\\keras\\engine\\training.py\", line 1030, in run_step  **\n        outputs = model.train_step(data)\n    File \"C:\\Users\\henry\\miniconda3\\envs\\jupyter_env\\lib\\site-packages\\keras\\engine\\training.py\", line 889, in train_step\n        y_pred = self(x, training=True)\n    File \"C:\\Users\\henry\\miniconda3\\envs\\jupyter_env\\lib\\site-packages\\keras\\utils\\traceback_utils.py\", line 67, in error_handler\n        raise e.with_traceback(filtered_tb) from None\n    File \"C:\\Users\\henry\\miniconda3\\envs\\jupyter_env\\lib\\site-packages\\keras\\engine\\input_spec.py\", line 214, in assert_input_compatibility\n        raise ValueError(f'Input {input_index} of layer \"{layer_name}\" '\n\n    ValueError: Exception encountered when calling layer \"sequential_2\" (type Sequential).\n    \n    Input 0 of layer \"lstm\" is incompatible with the layer: expected ndim=3, found ndim=1. Full shape received: (None,)\n    \n    Call arguments received by layer \"sequential_2\" (type Sequential):\n      • inputs=tf.Tensor(shape=(None,), dtype=float32)\n      • training=True\n      • mask=None\n",
     "output_type": "error",
     "traceback": [
      "\u001b[1;31m---------------------------------------------------------------------------\u001b[0m",
      "\u001b[1;31mValueError\u001b[0m                                Traceback (most recent call last)",
      "Input \u001b[1;32mIn [18]\u001b[0m, in \u001b[0;36m<cell line: 4>\u001b[1;34m()\u001b[0m\n\u001b[0;32m      2\u001b[0m Xtrain \u001b[38;5;241m=\u001b[39m np\u001b[38;5;241m.\u001b[39masarray(Xtrain)\u001b[38;5;241m.\u001b[39mastype(\u001b[38;5;124m'\u001b[39m\u001b[38;5;124mfloat32\u001b[39m\u001b[38;5;124m'\u001b[39m)\n\u001b[0;32m      3\u001b[0m ytrain \u001b[38;5;241m=\u001b[39m np\u001b[38;5;241m.\u001b[39masarray(ytrain)\u001b[38;5;241m.\u001b[39mastype(\u001b[38;5;124m'\u001b[39m\u001b[38;5;124mfloat32\u001b[39m\u001b[38;5;124m'\u001b[39m)\n\u001b[1;32m----> 4\u001b[0m \u001b[43mmodel\u001b[49m\u001b[38;5;241;43m.\u001b[39;49m\u001b[43mfit\u001b[49m\u001b[43m(\u001b[49m\u001b[43mXtrain\u001b[49m\u001b[43m,\u001b[49m\u001b[43m \u001b[49m\u001b[43mytrain\u001b[49m\u001b[43m,\u001b[49m\u001b[43m \u001b[49m\u001b[43mbatch_size\u001b[49m\u001b[38;5;241;43m=\u001b[39;49m\u001b[38;5;241;43m12\u001b[39;49m\u001b[43m,\u001b[49m\u001b[43m \u001b[49m\u001b[43mepochs\u001b[49m\u001b[38;5;241;43m=\u001b[39;49m\u001b[38;5;241;43m40\u001b[39;49m\u001b[43m)\u001b[49m\n",
      "File \u001b[1;32m~\\miniconda3\\envs\\jupyter_env\\lib\\site-packages\\keras\\utils\\traceback_utils.py:67\u001b[0m, in \u001b[0;36mfilter_traceback.<locals>.error_handler\u001b[1;34m(*args, **kwargs)\u001b[0m\n\u001b[0;32m     65\u001b[0m \u001b[38;5;28;01mexcept\u001b[39;00m \u001b[38;5;167;01mException\u001b[39;00m \u001b[38;5;28;01mas\u001b[39;00m e:  \u001b[38;5;66;03m# pylint: disable=broad-except\u001b[39;00m\n\u001b[0;32m     66\u001b[0m   filtered_tb \u001b[38;5;241m=\u001b[39m _process_traceback_frames(e\u001b[38;5;241m.\u001b[39m__traceback__)\n\u001b[1;32m---> 67\u001b[0m   \u001b[38;5;28;01mraise\u001b[39;00m e\u001b[38;5;241m.\u001b[39mwith_traceback(filtered_tb) \u001b[38;5;28;01mfrom\u001b[39;00m \u001b[38;5;28mNone\u001b[39m\n\u001b[0;32m     68\u001b[0m \u001b[38;5;28;01mfinally\u001b[39;00m:\n\u001b[0;32m     69\u001b[0m   \u001b[38;5;28;01mdel\u001b[39;00m filtered_tb\n",
      "File \u001b[1;32m~\\AppData\\Local\\Temp\\__autograph_generated_fileofz2h138.py:15\u001b[0m, in \u001b[0;36mouter_factory.<locals>.inner_factory.<locals>.tf__train_function\u001b[1;34m(iterator)\u001b[0m\n\u001b[0;32m     13\u001b[0m \u001b[38;5;28;01mtry\u001b[39;00m:\n\u001b[0;32m     14\u001b[0m     do_return \u001b[38;5;241m=\u001b[39m \u001b[38;5;28;01mTrue\u001b[39;00m\n\u001b[1;32m---> 15\u001b[0m     retval_ \u001b[38;5;241m=\u001b[39m ag__\u001b[38;5;241m.\u001b[39mconverted_call(ag__\u001b[38;5;241m.\u001b[39mld(step_function), (ag__\u001b[38;5;241m.\u001b[39mld(\u001b[38;5;28mself\u001b[39m), ag__\u001b[38;5;241m.\u001b[39mld(iterator)), \u001b[38;5;28;01mNone\u001b[39;00m, fscope)\n\u001b[0;32m     16\u001b[0m \u001b[38;5;28;01mexcept\u001b[39;00m:\n\u001b[0;32m     17\u001b[0m     do_return \u001b[38;5;241m=\u001b[39m \u001b[38;5;28;01mFalse\u001b[39;00m\n",
      "\u001b[1;31mValueError\u001b[0m: in user code:\n\n    File \"C:\\Users\\henry\\miniconda3\\envs\\jupyter_env\\lib\\site-packages\\keras\\engine\\training.py\", line 1051, in train_function  *\n        return step_function(self, iterator)\n    File \"C:\\Users\\henry\\miniconda3\\envs\\jupyter_env\\lib\\site-packages\\keras\\engine\\training.py\", line 1040, in step_function  **\n        outputs = model.distribute_strategy.run(run_step, args=(data,))\n    File \"C:\\Users\\henry\\miniconda3\\envs\\jupyter_env\\lib\\site-packages\\keras\\engine\\training.py\", line 1030, in run_step  **\n        outputs = model.train_step(data)\n    File \"C:\\Users\\henry\\miniconda3\\envs\\jupyter_env\\lib\\site-packages\\keras\\engine\\training.py\", line 889, in train_step\n        y_pred = self(x, training=True)\n    File \"C:\\Users\\henry\\miniconda3\\envs\\jupyter_env\\lib\\site-packages\\keras\\utils\\traceback_utils.py\", line 67, in error_handler\n        raise e.with_traceback(filtered_tb) from None\n    File \"C:\\Users\\henry\\miniconda3\\envs\\jupyter_env\\lib\\site-packages\\keras\\engine\\input_spec.py\", line 214, in assert_input_compatibility\n        raise ValueError(f'Input {input_index} of layer \"{layer_name}\" '\n\n    ValueError: Exception encountered when calling layer \"sequential_2\" (type Sequential).\n    \n    Input 0 of layer \"lstm\" is incompatible with the layer: expected ndim=3, found ndim=1. Full shape received: (None,)\n    \n    Call arguments received by layer \"sequential_2\" (type Sequential):\n      • inputs=tf.Tensor(shape=(None,), dtype=float32)\n      • training=True\n      • mask=None\n"
     ]
    }
   ],
   "source": [
    "model.compile(optimizer='adam', loss='mean_squared_error')\n",
    "Xtrain = np.asarray(Xtrain).astype('float32')\n",
    "ytrain = np.asarray(ytrain).astype('float32')\n",
    "model.fit(Xtrain, ytrain, batch_size=12, epochs=40)"
   ]
  },
  {
   "cell_type": "code",
   "execution_count": null,
   "id": "05290ad7",
   "metadata": {},
   "outputs": [],
   "source": []
  }
 ],
 "metadata": {
  "kernelspec": {
   "display_name": "TurinEnv",
   "language": "python",
   "name": "turinenv"
  },
  "language_info": {
   "codemirror_mode": {
    "name": "ipython",
    "version": 3
   },
   "file_extension": ".py",
   "mimetype": "text/x-python",
   "name": "python",
   "nbconvert_exporter": "python",
   "pygments_lexer": "ipython3",
   "version": "3.9.12"
  }
 },
 "nbformat": 4,
 "nbformat_minor": 5
}
